Traceback (most recent call last):
  File "/var/www/MISP/app/files/scripts/mispzmq/mispzmq.py", line 212, in <module>
    mzq = MispZmq()
  File "/var/www/MISP/app/files/scripts/mispzmq/mispzmq.py", line 70, in __init__
    raise Exception("mispzmq already running on PID {}".format(pid))
Exception: mispzmq already running on PID 88
Traceback (most recent call last):
  File "/var/www/MISP/app/files/scripts/mispzmq/mispzmq.py", line 212, in <module>
    mzq = MispZmq()
  File "/var/www/MISP/app/files/scripts/mispzmq/mispzmq.py", line 70, in __init__
    raise Exception("mispzmq already running on PID {}".format(pid))
Exception: mispzmq already running on PID 103
Traceback (most recent call last):
  File "/var/www/MISP/app/files/scripts/mispzmq/mispzmq.py", line 214, in <module>
Traceback (most recent call last):
  File "/var/www/MISP/app/files/scripts/mispzmq/mispzmq.py", line 212, in <module>
    mzq = MispZmq()
  File "/var/www/MISP/app/files/scripts/mispzmq/mispzmq.py", line 70, in __init__
    raise Exception("mispzmq already running on PID {}".format(pid))
Exception: mispzmq already running on PID 91
2023-09-09 18:51:39,743:INFO:root:Reload command received, reloading settings from file.
Traceback (most recent call last):
  File "/var/www/MISP/app/files/scripts/mispzmq/mispzmq.py", line 214, in <module>
    mzq.main()
  File "/var/www/MISP/app/files/scripts/mispzmq/mispzmq.py", line 161, in main
    self._setup_zmq()
  File "/var/www/MISP/app/files/scripts/mispzmq/mispzmq.py", line 108, in _setup_zmq
    self.socket.bind("tcp://{}:{}".format(self.settings["host"], self.settings["port"]))
  File "/usr/local/lib/python3.9/dist-packages/zmq/sugar/socket.py", line 302, in bind
    super().bind(addr)
  File "zmq/backend/cython/socket.pyx", line 564, in zmq.backend.cython.socket.Socket.bind
  File "zmq/backend/cython/checkrc.pxd", line 28, in zmq.backend.cython.checkrc._check_rc
zmq.error.ZMQError: Address already in use (addr='tcp://127.0.0.1:50000')
Traceback (most recent call last):
  File "/var/www/MISP/app/files/scripts/mispzmq/mispzmq.py", line 214, in <module>
Traceback (most recent call last):
  File "/var/www/MISP/app/files/scripts/mispzmq/mispzmq.py", line 212, in <module>
    mzq = MispZmq()
  File "/var/www/MISP/app/files/scripts/mispzmq/mispzmq.py", line 70, in __init__
    raise Exception("mispzmq already running on PID {}".format(pid))
Exception: mispzmq already running on PID 77
Traceback (most recent call last):
  File "/var/www/MISP/app/files/scripts/mispzmq/mispzmq.py", line 212, in <module>
    mzq = MispZmq()
  File "/var/www/MISP/app/files/scripts/mispzmq/mispzmq.py", line 70, in __init__
    raise Exception("mispzmq already running on PID {}".format(pid))
Exception: mispzmq already running on PID 93
Traceback (most recent call last):
  File "/var/www/MISP/app/files/scripts/mispzmq/mispzmq.py", line 214, in <module>
    mzq.main()
  File "/var/www/MISP/app/files/scripts/mispzmq/mispzmq.py", line 182, in main
    data = self.r.blpop(lists, timeout=10)
  File "/usr/local/lib/python3.9/dist-packages/redis/commands/core.py", line 2566, in blpop
Traceback (most recent call last):
  File "/var/www/MISP/app/files/scripts/mispzmq/mispzmq.py", line 212, in <module>
    mzq = MispZmq()
  File "/var/www/MISP/app/files/scripts/mispzmq/mispzmq.py", line 70, in __init__
    raise Exception("mispzmq already running on PID {}".format(pid))
Exception: mispzmq already running on PID 103
Traceback (most recent call last):
  File "/var/www/MISP/app/files/scripts/mispzmq/mispzmq.py", line 212, in <module>
    mzq = MispZmq()
  File "/var/www/MISP/app/files/scripts/mispzmq/mispzmq.py", line 70, in __init__
    raise Exception("mispzmq already running on PID {}".format(pid))
Exception: mispzmq already running on PID 82
Traceback (most recent call last):
  File "/var/www/MISP/app/files/scripts/mispzmq/mispzmq.py", line 212, in <module>
    mzq = MispZmq()
  File "/var/www/MISP/app/files/scripts/mispzmq/mispzmq.py", line 70, in __init__
    raise Exception("mispzmq already running on PID {}".format(pid))
Exception: mispzmq already running on PID 75
2023-09-12 19:26:23,229:INFO:root:Reload command received, reloading settings from file.
Traceback (most recent call last):
  File "/var/www/MISP/app/files/scripts/mispzmq/mispzmq.py", line 212, in <module>
    mzq = MispZmq()
  File "/var/www/MISP/app/files/scripts/mispzmq/mispzmq.py", line 70, in __init__
    raise Exception("mispzmq already running on PID {}".format(pid))
Exception: mispzmq already running on PID 85
Traceback (most recent call last):
  File "/var/www/MISP/app/files/scripts/mispzmq/mispzmq.py", line 212, in <module>
    mzq = MispZmq()
  File "/var/www/MISP/app/files/scripts/mispzmq/mispzmq.py", line 70, in __init__
    raise Exception("mispzmq already running on PID {}".format(pid))
Exception: mispzmq already running on PID 95
Traceback (most recent call last):
  File "/var/www/MISP/app/files/scripts/mispzmq/mispzmq.py", line 212, in <module>
    mzq = MispZmq()
  File "/var/www/MISP/app/files/scripts/mispzmq/mispzmq.py", line 70, in __init__
    raise Exception("mispzmq already running on PID {}".format(pid))
Exception: mispzmq already running on PID 83
Traceback (most recent call last):
  File "/var/www/MISP/app/files/scripts/mispzmq/mispzmq.py", line 214, in <module>
    mzq.main()
  File "/var/www/MISP/app/files/scripts/mispzmq/mispzmq.py", line 161, in main
    self._setup_zmq()
  File "/var/www/MISP/app/files/scripts/mispzmq/mispzmq.py", line 108, in _setup_zmq
    self.socket.bind("tcp://{}:{}".format(self.settings["host"], self.settings["port"]))
  File "/usr/local/lib/python3.9/dist-packages/zmq/sugar/socket.py", line 302, in bind
    super().bind(addr)
  File "zmq/backend/cython/socket.pyx", line 564, in zmq.backend.cython.socket.Socket.bind
  File "zmq/backend/cython/checkrc.pxd", line 28, in zmq.backend.cython.checkrc._check_rc
zmq.error.ZMQError: Address already in use (addr='tcp://127.0.0.1:50000')
Traceback (most recent call last):
  File "/var/www/MISP/app/files/scripts/mispzmq/mispzmq.py", line 212, in <module>
    mzq = MispZmq()
  File "/var/www/MISP/app/files/scripts/mispzmq/mispzmq.py", line 70, in __init__
    raise Exception("mispzmq already running on PID {}".format(pid))
Exception: mispzmq already running on PID 93
Traceback (most recent call last):
  File "/var/www/MISP/app/files/scripts/mispzmq/mispzmq.py", line 212, in <module>
    mzq = MispZmq()
  File "/var/www/MISP/app/files/scripts/mispzmq/mispzmq.py", line 70, in __init__
    raise Exception("mispzmq already running on PID {}".format(pid))
Exception: mispzmq already running on PID 106
Traceback (most recent call last):
  File "/var/www/MISP/app/files/scripts/mispzmq/mispzmq.py", line 214, in <module>
    mzq.main()
  File "/var/www/MISP/app/files/scripts/mispzmq/mispzmq.py", line 182, in main
    data = self.r.blpop(lists, timeout=10)
  File "/usr/local/lib/python3.9/dist-packages/redis/commands/core.py", line 2566, in blpop
Traceback (most recent call last):
  File "/var/www/MISP/app/files/scripts/mispzmq/mispzmq.py", line 212, in <module>
    mzq = MispZmq()
  File "/var/www/MISP/app/files/scripts/mispzmq/mispzmq.py", line 70, in __init__
    raise Exception("mispzmq already running on PID {}".format(pid))
Exception: mispzmq already running on PID 95
Traceback (most recent call last):
  File "/var/www/MISP/app/files/scripts/mispzmq/mispzmq.py", line 214, in <module>
    mzq.main()
  File "/var/www/MISP/app/files/scripts/mispzmq/mispzmq.py", line 182, in main
    data = self.r.blpop(lists, timeout=10)
  File "/usr/local/lib/python3.9/dist-packages/redis/commands/core.py", line 2566, in blpop
    return self.execute_command("BLPOP", *keys)
  File "/usr/local/lib/python3.9/dist-packages/redis/client.py", line 1269, in execute_command
    return conn.retry.call_with_retry(
  File "/usr/local/lib/python3.9/dist-packages/redis/retry.py", line 49, in call_with_retry
    fail(error)
  File "/usr/local/lib/python3.9/dist-packages/redis/client.py", line 1273, in <lambda>
    lambda error: self._disconnect_raise(conn, error),
  File "/usr/local/lib/python3.9/dist-packages/redis/client.py", line 1259, in _disconnect_raise
    raise error
  File "/usr/local/lib/python3.9/dist-packages/redis/retry.py", line 46, in call_with_retry
    return do()
  File "/usr/local/lib/python3.9/dist-packages/redis/client.py", line 1270, in <lambda>
    lambda: self._send_command_parse_response(
  File "/usr/local/lib/python3.9/dist-packages/redis/client.py", line 1246, in _send_command_parse_response
    return self.parse_response(conn, command_name, **options)
  File "/usr/local/lib/python3.9/dist-packages/redis/client.py", line 1286, in parse_response
    response = connection.read_response()
  File "/usr/local/lib/python3.9/dist-packages/redis/connection.py", line 874, in read_response
    response = self._parser.read_response(disable_decoding=disable_decoding)
  File "/usr/local/lib/python3.9/dist-packages/redis/connection.py", line 347, in read_response
    result = self._read_response(disable_decoding=disable_decoding)
  File "/usr/local/lib/python3.9/dist-packages/redis/connection.py", line 357, in _read_response
    raw = self._buffer.readline()
  File "/usr/local/lib/python3.9/dist-packages/redis/connection.py", line 260, in readline
    self._read_from_socket()
  File "/usr/local/lib/python3.9/dist-packages/redis/connection.py", line 213, in _read_from_socket
    raise ConnectionError(SERVER_CLOSED_CONNECTION_ERROR)
redis.exceptions.ConnectionError: Connection closed by server.
Traceback (most recent call last):
  File "/var/www/MISP/app/files/scripts/mispzmq/mispzmq.py", line 214, in <module>
    mzq.main()
  File "/var/www/MISP/app/files/scripts/mispzmq/mispzmq.py", line 161, in main
    self._setup_zmq()
  File "/var/www/MISP/app/files/scripts/mispzmq/mispzmq.py", line 108, in _setup_zmq
    self.socket.bind("tcp://{}:{}".format(self.settings["host"], self.settings["port"]))
  File "/usr/local/lib/python3.9/dist-packages/zmq/sugar/socket.py", line 302, in bind
    super().bind(addr)
  File "zmq/backend/cython/socket.pyx", line 564, in zmq.backend.cython.socket.Socket.bind
  File "zmq/backend/cython/checkrc.pxd", line 28, in zmq.backend.cython.checkrc._check_rc
zmq.error.ZMQError: Address already in use (addr='tcp://127.0.0.1:50000')
Traceback (most recent call last):
  File "/var/www/MISP/app/files/scripts/mispzmq/mispzmq.py", line 214, in <module>
    mzq.main()
  File "/var/www/MISP/app/files/scripts/mispzmq/mispzmq.py", line 182, in main
    data = self.r.blpop(lists, timeout=10)
  File "/usr/local/lib/python3.9/dist-packages/redis/commands/core.py", line 2566, in blpop
    return self.execute_command("BLPOP", *keys)
  File "/usr/local/lib/python3.9/dist-packages/redis/client.py", line 1269, in execute_command
    return conn.retry.call_with_retry(
  File "/usr/local/lib/python3.9/dist-packages/redis/retry.py", line 49, in call_with_retry
    fail(error)
  File "/usr/local/lib/python3.9/dist-packages/redis/client.py", line 1273, in <lambda>
    lambda error: self._disconnect_raise(conn, error),
  File "/usr/local/lib/python3.9/dist-packages/redis/client.py", line 1259, in _disconnect_raise
    raise error
  File "/usr/local/lib/python3.9/dist-packages/redis/retry.py", line 46, in call_with_retry
    return do()
  File "/usr/local/lib/python3.9/dist-packages/redis/client.py", line 1270, in <lambda>
    lambda: self._send_command_parse_response(
  File "/usr/local/lib/python3.9/dist-packages/redis/client.py", line 1246, in _send_command_parse_response
    return self.parse_response(conn, command_name, **options)
  File "/usr/local/lib/python3.9/dist-packages/redis/client.py", line 1286, in parse_response
    response = connection.read_response()
  File "/usr/local/lib/python3.9/dist-packages/redis/connection.py", line 874, in read_response
    response = self._parser.read_response(disable_decoding=disable_decoding)
  File "/usr/local/lib/python3.9/dist-packages/redis/connection.py", line 347, in read_response
    result = self._read_response(disable_decoding=disable_decoding)
  File "/usr/local/lib/python3.9/dist-packages/redis/connection.py", line 357, in _read_response
    raw = self._buffer.readline()
  File "/usr/local/lib/python3.9/dist-packages/redis/connection.py", line 260, in readline
    self._read_from_socket()
  File "/usr/local/lib/python3.9/dist-packages/redis/connection.py", line 213, in _read_from_socket
    raise ConnectionError(SERVER_CLOSED_CONNECTION_ERROR)
redis.exceptions.ConnectionError: Connection closed by server.
Traceback (most recent call last):
Traceback (most recent call last):
  File "/var/www/MISP/app/files/scripts/mispzmq/mispzmq.py", line 214, in <module>
  File "/var/www/MISP/app/files/scripts/mispzmq/mispzmq.py", line 214, in <module>
    mzq.main()
    mzq.main()
  File "/var/www/MISP/app/files/scripts/mispzmq/mispzmq.py", line 161, in main
  File "/var/www/MISP/app/files/scripts/mispzmq/mispzmq.py", line 161, in main
    self._setup_zmq()
    self._setup_zmq()
  File "/var/www/MISP/app/files/scripts/mispzmq/mispzmq.py", line 108, in _setup_zmq
  File "/var/www/MISP/app/files/scripts/mispzmq/mispzmq.py", line 108, in _setup_zmq
    self.socket.bind("tcp://{}:{}".format(self.settings["host"], self.settings["port"]))
    self.socket.bind("tcp://{}:{}".format(self.settings["host"], self.settings["port"]))
  File "/usr/local/lib/python3.9/dist-packages/zmq/sugar/socket.py", line 302, in bind
  File "/usr/local/lib/python3.9/dist-packages/zmq/sugar/socket.py", line 302, in bind
    super().bind(addr)
  File "zmq/backend/cython/socket.pyx", line 564, in zmq.backend.cython.socket.Socket.bind
  File "zmq/backend/cython/checkrc.pxd", line 28, in zmq.backend.cython.checkrc._check_rc
zmq.error.ZMQError: Address already in use (addr='tcp://127.0.0.1:50000')
    super().bind(addr)
  File "zmq/backend/cython/socket.pyx", line 564, in zmq.backend.cython.socket.Socket.bind
  File "zmq/backend/cython/checkrc.pxd", line 28, in zmq.backend.cython.checkrc._check_rc
zmq.error.ZMQError: Address already in use (addr='tcp://127.0.0.1:50000')
Traceback (most recent call last):
  File "/var/www/MISP/app/files/scripts/mispzmq/mispzmq.py", line 214, in <module>
    mzq.main()
  File "/var/www/MISP/app/files/scripts/mispzmq/mispzmq.py", line 161, in main
    self._setup_zmq()
  File "/var/www/MISP/app/files/scripts/mispzmq/mispzmq.py", line 108, in _setup_zmq
    self.socket.bind("tcp://{}:{}".format(self.settings["host"], self.settings["port"]))
  File "/usr/local/lib/python3.9/dist-packages/zmq/sugar/socket.py", line 302, in bind
    super().bind(addr)
  File "zmq/backend/cython/socket.pyx", line 564, in zmq.backend.cython.socket.Socket.bind
  File "zmq/backend/cython/checkrc.pxd", line 28, in zmq.backend.cython.checkrc._check_rc
zmq.error.ZMQError: Address already in use (addr='tcp://127.0.0.1:50000')
Traceback (most recent call last):
  File "/var/www/MISP/app/files/scripts/mispzmq/mispzmq.py", line 212, in <module>
    mzq = MispZmq()
  File "/var/www/MISP/app/files/scripts/mispzmq/mispzmq.py", line 70, in __init__
    raise Exception("mispzmq already running on PID {}".format(pid))
Exception: mispzmq already running on PID 84
Traceback (most recent call last):
  File "/var/www/MISP/app/files/scripts/mispzmq/mispzmq.py", line 212, in <module>
    mzq = MispZmq()
  File "/var/www/MISP/app/files/scripts/mispzmq/mispzmq.py", line 70, in __init__
    raise Exception("mispzmq already running on PID {}".format(pid))
Exception: mispzmq already running on PID 94
Traceback (most recent call last):
  File "/var/www/MISP/app/files/scripts/mispzmq/mispzmq.py", line 212, in <module>
    mzq = MispZmq()
  File "/var/www/MISP/app/files/scripts/mispzmq/mispzmq.py", line 70, in __init__
    raise Exception("mispzmq already running on PID {}".format(pid))
Exception: mispzmq already running on PID 95
Traceback (most recent call last):
  File "/var/www/MISP/app/files/scripts/mispzmq/mispzmq.py", line 212, in <module>
    mzq = MispZmq()
  File "/var/www/MISP/app/files/scripts/mispzmq/mispzmq.py", line 70, in __init__
    raise Exception("mispzmq already running on PID {}".format(pid))
Exception: mispzmq already running on PID 72
Traceback (most recent call last):
  File "/var/www/MISP/app/files/scripts/mispzmq/mispzmq.py", line 212, in <module>
    mzq = MispZmq()
  File "/var/www/MISP/app/files/scripts/mispzmq/mispzmq.py", line 70, in __init__
    raise Exception("mispzmq already running on PID {}".format(pid))
Exception: mispzmq already running on PID 83
2023-09-15 21:41:16,727:INFO:root:Reload command received, reloading settings from file.
Traceback (most recent call last):
  File "/var/www/MISP/app/files/scripts/mispzmq/mispzmq.py", line 212, in <module>
    mzq = MispZmq()
  File "/var/www/MISP/app/files/scripts/mispzmq/mispzmq.py", line 70, in __init__
    raise Exception("mispzmq already running on PID {}".format(pid))
Exception: mispzmq already running on PID 85
Traceback (most recent call last):
  File "/var/www/MISP/app/files/scripts/mispzmq/mispzmq.py", line 212, in <module>
    mzq = MispZmq()
  File "/var/www/MISP/app/files/scripts/mispzmq/mispzmq.py", line 70, in __init__
    raise Exception("mispzmq already running on PID {}".format(pid))
Exception: mispzmq already running on PID 93
Traceback (most recent call last):
  File "/var/www/MISP/app/files/scripts/mispzmq/mispzmq.py", line 212, in <module>
    mzq = MispZmq()
  File "/var/www/MISP/app/files/scripts/mispzmq/mispzmq.py", line 70, in __init__
    raise Exception("mispzmq already running on PID {}".format(pid))
Exception: mispzmq already running on PID 84
Traceback (most recent call last):
  File "/var/www/MISP/app/files/scripts/mispzmq/mispzmq.py", line 212, in <module>
    mzq = MispZmq()
  File "/var/www/MISP/app/files/scripts/mispzmq/mispzmq.py", line 70, in __init__
    raise Exception("mispzmq already running on PID {}".format(pid))
Exception: mispzmq already running on PID 93
Traceback (most recent call last):
  File "/var/www/MISP/app/files/scripts/mispzmq/mispzmq.py", line 214, in <module>
    mzq.main()
  File "/var/www/MISP/app/files/scripts/mispzmq/mispzmq.py", line 182, in main
    data = self.r.blpop(lists, timeout=10)
  File "/usr/local/lib/python3.9/dist-packages/redis/commands/core.py", line 2566, in blpop
    return self.execute_command("BLPOP", *keys)
  File "/usr/local/lib/python3.9/dist-packages/redis/client.py", line 1269, in execute_command
    return conn.retry.call_with_retry(
  File "/usr/local/lib/python3.9/dist-packages/redis/retry.py", line 49, in call_with_retry
    fail(error)
  File "/usr/local/lib/python3.9/dist-packages/redis/client.py", line 1273, in <lambda>
    lambda error: self._disconnect_raise(conn, error),
  File "/usr/local/lib/python3.9/dist-packages/redis/client.py", line 1259, in _disconnect_raise
    raise error
  File "/usr/local/lib/python3.9/dist-packages/redis/retry.py", line 46, in call_with_retry
    return do()
  File "/usr/local/lib/python3.9/dist-packages/redis/client.py", line 1270, in <lambda>
    lambda: self._send_command_parse_response(
  File "/usr/local/lib/python3.9/dist-packages/redis/client.py", line 1246, in _send_command_parse_response
    return self.parse_response(conn, command_name, **options)
  File "/usr/local/lib/python3.9/dist-packages/redis/client.py", line 1286, in parse_response
    response = connection.read_response()
  File "/usr/local/lib/python3.9/dist-packages/redis/connection.py", line 874, in read_response
    response = self._parser.read_response(disable_decoding=disable_decoding)
  File "/usr/local/lib/python3.9/dist-packages/redis/connection.py", line 347, in read_response
    result = self._read_response(disable_decoding=disable_decoding)
  File "/usr/local/lib/python3.9/dist-packages/redis/connection.py", line 357, in _read_response
    raw = self._buffer.readline()
  File "/usr/local/lib/python3.9/dist-packages/redis/connection.py", line 260, in readline
    self._read_from_socket()
  File "/usr/local/lib/python3.9/dist-packages/redis/connection.py", line 213, in _read_from_socket
    raise ConnectionError(SERVER_CLOSED_CONNECTION_ERROR)
redis.exceptions.ConnectionError: Connection closed by server.
Traceback (most recent call last):
  File "/var/www/MISP/app/files/scripts/mispzmq/mispzmq.py", line 214, in <module>
    mzq.main()
  File "/var/www/MISP/app/files/scripts/mispzmq/mispzmq.py", line 161, in main
    self._setup_zmq()
  File "/var/www/MISP/app/files/scripts/mispzmq/mispzmq.py", line 108, in _setup_zmq
    self.socket.bind("tcp://{}:{}".format(self.settings["host"], self.settings["port"]))
  File "/usr/local/lib/python3.9/dist-packages/zmq/sugar/socket.py", line 302, in bind
    super().bind(addr)
  File "zmq/backend/cython/socket.pyx", line 564, in zmq.backend.cython.socket.Socket.bind
  File "zmq/backend/cython/checkrc.pxd", line 28, in zmq.backend.cython.checkrc._check_rc
zmq.error.ZMQError: Address already in use (addr='tcp://127.0.0.1:50000')
Traceback (most recent call last):
Traceback (most recent call last):
  File "/var/www/MISP/app/files/scripts/mispzmq/mispzmq.py", line 214, in <module>
    mzq.main()
  File "/var/www/MISP/app/files/scripts/mispzmq/mispzmq.py", line 161, in main
    self._setup_zmq()
  File "/var/www/MISP/app/files/scripts/mispzmq/mispzmq.py", line 108, in _setup_zmq
    self.socket.bind("tcp://{}:{}".format(self.settings["host"], self.settings["port"]))
  File "/usr/local/lib/python3.9/dist-packages/zmq/sugar/socket.py", line 302, in bind
    super().bind(addr)
  File "zmq/backend/cython/socket.pyx", line 564, in zmq.backend.cython.socket.Socket.bind
  File "zmq/backend/cython/checkrc.pxd", line 28, in zmq.backend.cython.checkrc._check_rc
zmq.error.ZMQError: Address already in use (addr='tcp://127.0.0.1:50000')
Traceback (most recent call last):
  File "/var/www/MISP/app/files/scripts/mispzmq/mispzmq.py", line 214, in <module>
    mzq.main()
  File "/var/www/MISP/app/files/scripts/mispzmq/mispzmq.py", line 182, in main
    data = self.r.blpop(lists, timeout=10)
  File "/usr/local/lib/python3.9/dist-packages/redis/commands/core.py", line 2566, in blpop
    return self.execute_command("BLPOP", *keys)
  File "/usr/local/lib/python3.9/dist-packages/redis/client.py", line 1269, in execute_command
    return conn.retry.call_with_retry(
  File "/usr/local/lib/python3.9/dist-packages/redis/retry.py", line 49, in call_with_retry
    fail(error)
  File "/usr/local/lib/python3.9/dist-packages/redis/client.py", line 1273, in <lambda>
    lambda error: self._disconnect_raise(conn, error),
  File "/usr/local/lib/python3.9/dist-packages/redis/client.py", line 1259, in _disconnect_raise
    raise error
  File "/usr/local/lib/python3.9/dist-packages/redis/retry.py", line 46, in call_with_retry
    return do()
  File "/usr/local/lib/python3.9/dist-packages/redis/client.py", line 1270, in <lambda>
    lambda: self._send_command_parse_response(
  File "/usr/local/lib/python3.9/dist-packages/redis/client.py", line 1246, in _send_command_parse_response
    return self.parse_response(conn, command_name, **options)
  File "/usr/local/lib/python3.9/dist-packages/redis/client.py", line 1286, in parse_response
    response = connection.read_response()
  File "/usr/local/lib/python3.9/dist-packages/redis/connection.py", line 874, in read_response
    response = self._parser.read_response(disable_decoding=disable_decoding)
  File "/usr/local/lib/python3.9/dist-packages/redis/connection.py", line 347, in read_response
    result = self._read_response(disable_decoding=disable_decoding)
  File "/usr/local/lib/python3.9/dist-packages/redis/connection.py", line 357, in _read_response
    raw = self._buffer.readline()
  File "/usr/local/lib/python3.9/dist-packages/redis/connection.py", line 260, in readline
    self._read_from_socket()
  File "/usr/local/lib/python3.9/dist-packages/redis/connection.py", line 213, in _read_from_socket
    raise ConnectionError(SERVER_CLOSED_CONNECTION_ERROR)
redis.exceptions.ConnectionError: Connection closed by server.
